[2025-02-22T13:01:04.532-0300] {local_task_job_runner.py:123} INFO - ::group::Pre task execution logs
[2025-02-22T13:01:04.539-0300] {taskinstance.py:2614} INFO - Dependencies all met for dep_context=non-requeueable deps ti=<TaskInstance: fii_info.transform.transform manual__2025-02-22T16:00:59.958492+00:00 [queued]>
[2025-02-22T13:01:04.543-0300] {taskinstance.py:2614} INFO - Dependencies all met for dep_context=requeueable deps ti=<TaskInstance: fii_info.transform.transform manual__2025-02-22T16:00:59.958492+00:00 [queued]>
[2025-02-22T13:01:04.543-0300] {taskinstance.py:2867} INFO - Starting attempt 1 of 1
[2025-02-22T13:01:04.554-0300] {taskinstance.py:2890} INFO - Executing <Task(_PythonDecoratedOperator): transform.transform> on 2025-02-22 16:00:59.958492+00:00
[2025-02-22T13:01:04.557-0300] {standard_task_runner.py:72} INFO - Started process 18541 to run task
[2025-02-22T13:01:04.558-0300] {standard_task_runner.py:104} INFO - Running: ['airflow', 'tasks', 'run', 'fii_info', 'transform.transform', 'manual__2025-02-22T16:00:59.958492+00:00', '--job-id', '7', '--raw', '--subdir', 'DAGS_FOLDER/info_Fii.py', '--cfg-path', '/tmp/tmpu97s3wi6']
[2025-02-22T13:01:04.560-0300] {standard_task_runner.py:105} INFO - Job 7: Subtask transform.transform
[2025-02-22T13:01:04.583-0300] {task_command.py:467} INFO - Running <TaskInstance: fii_info.transform.transform manual__2025-02-22T16:00:59.958492+00:00 [running]> on host LAPTOP-3G01DURD.
[2025-02-22T13:01:04.686-0300] {taskinstance.py:3134} INFO - Exporting env vars: AIRFLOW_CTX_DAG_OWNER='airflow' AIRFLOW_CTX_DAG_ID='fii_info' AIRFLOW_CTX_TASK_ID='transform.transform' AIRFLOW_CTX_EXECUTION_DATE='2025-02-22T16:00:59.958492+00:00' AIRFLOW_CTX_TRY_NUMBER='1' AIRFLOW_CTX_DAG_RUN_ID='manual__2025-02-22T16:00:59.958492+00:00'
[2025-02-22T13:01:04.687-0300] {taskinstance.py:732} INFO - ::endgroup::
[2025-02-22T13:01:04.690-0300] {taskinstance.py:3313} ERROR - Task failed with exception
Traceback (most recent call last):
  File "/home/lpimenta/pipelineAf/airflow_env/lib/python3.10/site-packages/airflow/models/taskinstance.py", line 768, in _execute_task
    result = _execute_callable(context=context, **execute_callable_kwargs)
  File "/home/lpimenta/pipelineAf/airflow_env/lib/python3.10/site-packages/airflow/models/taskinstance.py", line 734, in _execute_callable
    return ExecutionCallableRunner(
  File "/home/lpimenta/pipelineAf/airflow_env/lib/python3.10/site-packages/airflow/utils/operator_helpers.py", line 252, in run
    return self.func(*args, **kwargs)
  File "/home/lpimenta/pipelineAf/airflow_env/lib/python3.10/site-packages/airflow/models/baseoperator.py", line 424, in wrapper
    return func(self, *args, **kwargs)
  File "/home/lpimenta/pipelineAf/airflow_env/lib/python3.10/site-packages/airflow/decorators/base.py", line 266, in execute
    return_value = super().execute(context)
  File "/home/lpimenta/pipelineAf/airflow_env/lib/python3.10/site-packages/airflow/models/baseoperator.py", line 424, in wrapper
    return func(self, *args, **kwargs)
  File "/home/lpimenta/pipelineAf/airflow_env/lib/python3.10/site-packages/airflow/operators/python.py", line 238, in execute
    return_value = self.execute_callable()
  File "/home/lpimenta/pipelineAf/airflow_env/lib/python3.10/site-packages/airflow/operators/python.py", line 256, in execute_callable
    return runner.run(*self.op_args, **self.op_kwargs)
  File "/home/lpimenta/pipelineAf/airflow_env/lib/python3.10/site-packages/airflow/utils/operator_helpers.py", line 252, in run
    return self.func(*args, **kwargs)
  File "/home/lpimenta/pipelineAf/dags/info_Fii.py", line 37, in process_data
    dados_close=pd.melt(dados_close,id_vars=['Date'],value_vars=tickers,var_name="FII",value_name="Close")
NameError: name 'tickers' is not defined
[2025-02-22T13:01:04.692-0300] {taskinstance.py:1226} INFO - Marking task as FAILED. dag_id=fii_info, task_id=transform.transform, run_id=manual__2025-02-22T16:00:59.958492+00:00, execution_date=20250222T160059, start_date=20250222T160104, end_date=20250222T160104
[2025-02-22T13:01:04.708-0300] {taskinstance.py:341} INFO - ::group::Post task execution logs
[2025-02-22T13:01:04.709-0300] {standard_task_runner.py:124} ERROR - Failed to execute job 7 for task transform.transform (name 'tickers' is not defined; 18541)
Traceback (most recent call last):
  File "/home/lpimenta/pipelineAf/airflow_env/lib/python3.10/site-packages/airflow/task/task_runner/standard_task_runner.py", line 117, in _start_by_fork
    ret = args.func(args, dag=self.dag)
  File "/home/lpimenta/pipelineAf/airflow_env/lib/python3.10/site-packages/airflow/cli/cli_config.py", line 49, in command
    return func(*args, **kwargs)
  File "/home/lpimenta/pipelineAf/airflow_env/lib/python3.10/site-packages/airflow/utils/cli.py", line 116, in wrapper
    return f(*args, **kwargs)
  File "/home/lpimenta/pipelineAf/airflow_env/lib/python3.10/site-packages/airflow/cli/commands/task_command.py", line 483, in task_run
    task_return_code = _run_task_by_selected_method(args, _dag, ti)
  File "/home/lpimenta/pipelineAf/airflow_env/lib/python3.10/site-packages/airflow/cli/commands/task_command.py", line 256, in _run_task_by_selected_method
    return _run_raw_task(args, ti)
  File "/home/lpimenta/pipelineAf/airflow_env/lib/python3.10/site-packages/airflow/cli/commands/task_command.py", line 341, in _run_raw_task
    return ti._run_raw_task(
  File "/home/lpimenta/pipelineAf/airflow_env/lib/python3.10/site-packages/airflow/utils/session.py", line 97, in wrapper
    return func(*args, session=session, **kwargs)
  File "/home/lpimenta/pipelineAf/airflow_env/lib/python3.10/site-packages/airflow/models/taskinstance.py", line 3006, in _run_raw_task
    return _run_raw_task(
  File "/home/lpimenta/pipelineAf/airflow_env/lib/python3.10/site-packages/airflow/models/taskinstance.py", line 274, in _run_raw_task
    TaskInstance._execute_task_with_callbacks(
  File "/home/lpimenta/pipelineAf/airflow_env/lib/python3.10/site-packages/airflow/models/taskinstance.py", line 3161, in _execute_task_with_callbacks
    result = self._execute_task(context, task_orig)
  File "/home/lpimenta/pipelineAf/airflow_env/lib/python3.10/site-packages/airflow/models/taskinstance.py", line 3185, in _execute_task
    return _execute_task(self, context, task_orig)
  File "/home/lpimenta/pipelineAf/airflow_env/lib/python3.10/site-packages/airflow/models/taskinstance.py", line 768, in _execute_task
    result = _execute_callable(context=context, **execute_callable_kwargs)
  File "/home/lpimenta/pipelineAf/airflow_env/lib/python3.10/site-packages/airflow/models/taskinstance.py", line 734, in _execute_callable
    return ExecutionCallableRunner(
  File "/home/lpimenta/pipelineAf/airflow_env/lib/python3.10/site-packages/airflow/utils/operator_helpers.py", line 252, in run
    return self.func(*args, **kwargs)
  File "/home/lpimenta/pipelineAf/airflow_env/lib/python3.10/site-packages/airflow/models/baseoperator.py", line 424, in wrapper
    return func(self, *args, **kwargs)
  File "/home/lpimenta/pipelineAf/airflow_env/lib/python3.10/site-packages/airflow/decorators/base.py", line 266, in execute
    return_value = super().execute(context)
  File "/home/lpimenta/pipelineAf/airflow_env/lib/python3.10/site-packages/airflow/models/baseoperator.py", line 424, in wrapper
    return func(self, *args, **kwargs)
  File "/home/lpimenta/pipelineAf/airflow_env/lib/python3.10/site-packages/airflow/operators/python.py", line 238, in execute
    return_value = self.execute_callable()
  File "/home/lpimenta/pipelineAf/airflow_env/lib/python3.10/site-packages/airflow/operators/python.py", line 256, in execute_callable
    return runner.run(*self.op_args, **self.op_kwargs)
  File "/home/lpimenta/pipelineAf/airflow_env/lib/python3.10/site-packages/airflow/utils/operator_helpers.py", line 252, in run
    return self.func(*args, **kwargs)
  File "/home/lpimenta/pipelineAf/dags/info_Fii.py", line 37, in process_data
    dados_close=pd.melt(dados_close,id_vars=['Date'],value_vars=tickers,var_name="FII",value_name="Close")
NameError: name 'tickers' is not defined
[2025-02-22T13:01:04.731-0300] {local_task_job_runner.py:266} INFO - Task exited with return code 1
[2025-02-22T13:01:04.739-0300] {taskinstance.py:3901} INFO - 0 downstream tasks scheduled from follow-on schedule check
[2025-02-22T13:01:04.747-0300] {local_task_job_runner.py:245} INFO - ::endgroup::
